Workbook

Sheet HowTo
B1: Einleitung – Zweck des Tools
B3: Die Basis für jedes Projekt ist der BluePrint, der die vollständige Umsetzung beschreibt und idealerweise zu 100 % realisiert werden soll.
B4: Aus diesem Blueprint wird der PLAN-Stand abgeleitet – eine angepasste Version, die während der Angebots- und Verhandlungsphase definiert und vertraglich festgelegt wird.
B7: In Q2 2026 wird vorraussichtlich ein automatisiertes Tool folgen und die Excel ablösen, wodurch DevOps auch direkt integriert wird, sodass alles
B8: an einem Ort ist, was zum Blueprint-Assesment zählt
B10: Begriffserklärung
B12: BluePrint: Standardvorgabe für die Projektumsetzung, Ziel ist eine vollständige Realisierung.
B13: PLAN-Stand: Angepasste Version des BluePrints (Tailoring), die während der Angebots- und Verhandlungsphase festgelegt wird.
B14: IST-Stand: Tatsächlich erreichte Werte während der Projektlaufzeit.
B15: Erfüllungsgrad: Vergleich zwischen PLAN und IST über die gesamte Projektlaufzeit.
B16: Compliance Check: Regelmäßige Erfassung des IST-Standes und Abgleich mit dem PLAN-Stand.
B18: Arbeitsablauf (Workflow)
... B21: Zuerst wird der PLAN-Stand ermittelt und im Tabellenblatt „Plan Stand“ ausgefüllt. Dieser Stand gilt als Referenz für alle späteren IST-Erfassungen.
B23: Status - PLAN-Stand | C23: Punktewert | D23: Erklärung
B24: Erfüllt | C24: Alle Punkte, die erfüllt sind | D24: Der jeweilige Punkt soll wie im Blueprint beschrieben umgesetzt werden
B25: Teilweise | C25: Alle Punkte, die teilweise erfüllt sind | D25: Der jeweilige Punkt soll teilweise nach dem Blueprint umgesetzt werden (Tailoringhinweis ergänzen)
B26: Nicht erfüllt | C26: Alle Punkte, die nicht erfüllt sind | D26: Der jeweilige Punkt wird abweichend zum Blueprint umgesetzt (Tailoringhinweis ergänzen)
B27: Out of Scope | C27: Alle Punkte, die im Projekt nicht benötigt werden | D27: z.B: Shoring Blueprint in einem nicht Shoring-Projekt
B29: 2. Vorlage für IST-Blätter
B30: Aus „Plan Stand“ wird die Spalte „Plan-Status“ in das Blatt "IST Stand <Datum> " kopiert. Dieses Blatt dient als Vorlage für wiederkehrende IST-Erfassungen.
B32: 3. Die Vorlage wird kopiert.
B33: Datum, Quartal oder Monat werden im Blattnamen manuell eingetragen (einheitliche Benennung, z. B. IST Stand 2026-Q1)
B35: Wichtig – Verknüpfung mit „Erfüllungsgrad“:
B36: Im Tabellenblatt „Erfüllungsgrad“ muss in Zeile 2 derselbe Eintrag stehen wie der Name des IST-Blatts (z. B. IST Stand 2026-Q1).
B37: Nur wenn Blattname und Eintrag in Zeile 2 exakt übereinstimmen, funktionieren die Verlinkungen in der Auswertung
B39: 4. IST-Stand erfassen
B40: Erst danach wird der IST-Stand des Projekts fortlaufend im jeweiligen IST-Blatt dokumentiert.
B42: Status - IST-Stand | C42: Punktewert | D42: Erklärung
B43: Erfüllt | C43: Alle Punkte, die erfüllt sind | D43: Der jeweilige Punkt ist wie im Blueprint beschrieben umgesetzt
B44: Teilweise | C44: Alle Punkte, die teilweise erfüllt sind | D44: Der jeweilige Punkt ist teilweise wie im Blueprint beschrieben umgesetzt (Abweichung kommentieren)
B45: Nicht erfüllt | C45: Alle Punkte, die nicht erfüllt sind | D45: Der jeweilige Punkt ist nicht nach Blueprint umgesetzt (Abweichung kommentieren)
B46: Out of Scope | C46: Alle Punkte, die im Projekt nicht benötigt werden | D46: z.B: Shoring Blueprint in einem nicht Shoring-Projekt
B48: 5. DevOps Compliance
B49: Für DevOps wird das folgende Template ausgefüllt: | D49: DevOps Umfrage
B50: Hinweise zur DevOps Umfrage sind hier zu finden: | D50: DevOps Check-up
B51: Das Ergebnis des Templates soll dann entsprechend neben dieser Excel Datei gespeichert und entsprechend Versioniert werden.
B52: Umrechnung DevOps Score: Punkte = Prozentsatz (Beispiel: 4.5 Punkte = 45%)
B54: STQB
B56: 1. STQB Werte
B57: Die Werte für das STQB-Jira werden in demTabellenblatt "Erfüllungsgrad" ab Zeile 42 angezeigt.
...

Sheet Erfüllungsgrad
A1: Erfüllungsgrad | D1: ℹ️Tabellennamen der IST-Stände bitte manuell ergänzen
A2: Capability | C2: PLAN Stand | D2: IST Stand <Datum> | I2: =IFERROR(REPLACE(INDEX(Blattnamen,COLUMN(#REF!)),1,FIND("]",INDEX(Blattnamen,COLUMN(#REF!))),""),"") | J2: =IFERROR(REPLACE(INDEX(Blattnamen,COLUMN(#REF!)),1,FIND("]",INDEX(Blattnamen,COLUMN(#REF!))),""),"") | K2: =IFERROR(REPLACE(INDEX(Blattnamen,COLUMN(#REF!)),1,FIND("]",INDEX(Blattnamen,COLUMN(#REF!))),""),"") | L2: =IFERROR(REPLACE(INDEX(Blattnamen,COLUMN(#REF!)),1,FIND("]",INDEX(Blattnamen,COLUMN(#REF!))),""),"") | M2: =IFERROR(REPLACE(INDEX(Blattnamen,COLUMN(#REF!)),1,FIND("]",INDEX(Blattnamen,COLUMN(#REF!))),""),"") | N2: =IFERROR(REPLACE(INDEX(Blattnamen,COLUMN(#REF!)),1,FIND("]",INDEX(Blattnamen,COLUMN(#REF!))),""),"") | O2: =IFERROR(REPLACE(INDEX(Blattnamen,COLUMN(#REF!)),1,FIND("]",INDEX(Blattnamen,COLUMN(#REF!))),""),"") | P2: =IFERROR(REPLACE(INDEX(Blattnamen,COLUMN(#REF!)),1,FIND("]",INDEX(Blattnamen,COLUMN(#REF!))),""),"") | ... CY2: =IFERROR(REPLACE(INDEX(Blattnamen,COLUMN(#REF!)),1,FIND("]",INDEX(Blattnamen,COLUMN(#REF!))),""),"")
A3: Architektur | C3: =IF(OR($C$16="",SUM(C18:C21)<$C17),"",IF(SUM(C$18:C$20)<>0,(C$18*1+C$19*0.5)/SUM(C$18:C$20),0)) -> 0 | D3: =_xlfn.IFS(OR(D$16="",SUM($C$18:$C$21)<$C17,SUM(D$18:D$21)<$C18),"",AND(SUM($C$18:$C$20)=0,$C$21>0),"0",SUM(D$18:D$20)=0,0,SUM(D$18:D$20)<>0,(D$18*1+D$19*0.5)/SUM($C$18:$C$20)) -> 0 | E3: =_xlfn.IFS(OR(E$16="",SUM($C$18:$C$21)<$C17,SUM(E$18:E$21)<$C18),"",AND(SUM($C$18:$C$20)=0,$C$21>0),"n/a",SUM(E$18:E$20)=0,0,SUM(E$18:E$20)<>0,(E$18*1+E$19*0.5)/SUM($C$18:$C$20)) | F3: =_xlfn.IFS(OR(F$16="",SUM($C$18:$C$21)<$C17,SUM(F$18:F$21)<$C18),"",AND(SUM($C$18:$C$20)=0,$C$21>0),"n/a",SUM(F$18:F$20)=0,0,SUM(F$18:F$20)<>0,(F$18*1+F$19*0.5)/SUM($C$18:$C$20)) | G3: =_xlfn.IFS(OR(G$16="",SUM($C$18:$C$21)<$C17,SUM(G$18:G$21)<$C18),"",AND(SUM($C$18:$C$20)=0,$C$21>0),"n/a",SUM(G$18:G$20)=0,0,SUM(G$18:G$20)<>0,(G$18*1+G$19*0.5)/SUM($C$18:$C$20)) | H3: =_xlfn.IFS(OR(H$16="",SUM($C$18:$C$21)<$C17,SUM(H$18:H$21)<$C18),"",AND(SUM($C$18:$C$20)=0,$C$21>0),"n/a",SUM(H$18:H$20)=0,0,SUM(H$18:H$20)<>0,(H$18*1+H$19*0.5)/SUM($C$18:$C$20)) | I3: =_xlfn.IFS(OR(I$16="",SUM($C$18:$C$21)<$C17,SUM(I$18:I$21)<$C18),"",AND(SUM($C$18:$C$20)=0,$C$21>0),"n/a",SUM(I$18:I$20)=0,0,SUM(I$18:I$20)<>0,(I$18*1+I$19*0.5)/SUM($C$18:$C$20)) | J3: =_xlfn.IFS(OR(J$16="",SUM($C$18:$C$21)<$C17,SUM(J$18:J$21)<$C18),"",AND(SUM($C$18:$C$20)=0,$C$21>0),"n/a",SUM(J$18:J$20)=0,0,SUM(J$18:J$20)<>0,(J$18*1+J$19*0.5)/SUM($C$18:$C$20)) | K3: =_xlfn.IFS(OR(K$16="",SUM($C$18:$C$21)<$C17,SUM(K$18:K$21)<$C18),"",AND(SUM($C$18:$C$20)=0,$C$21>0),"n/a",SUM(K$18:K$20)=0,0,SUM(K$18:K$20)<>0,(K$18*1+K$19*0.5)/SUM($C$18:$C$20)) | L3: =_xlfn.IFS(OR(L$16="",SUM($C$18:$C$21)<$C17,SUM(L$18:L$21)<$C18),"",AND(SUM($C$18:$C$20)=0,$C$21>0),"n/a",SUM(L$18:L$20)=0,0,SUM(L$18:L$20)<>0,(L$18*1+L$19*0.5)/SUM($C$18:$C$20)) | ... CY3: =_xlfn.IFS(OR(CY$16="",SUM($C$18:$C$21)<$C17,SUM(CY$18:CY$21)<$C18),"",AND(SUM($C$18:$C$20)=0,$C$21>0),"n/a",SUM(CY$18:CY$20)=0,0,SUM(CY$18:CY$20)<>0,(CY$18*1+CY$19*0.5)/SUM($C$18:$C$20))
A4: Projektmanagement | C4: =IF(OR($C$16="",SUM(C23:C26)<$C22),"",IF(SUM(C$23:C$25)<>0,(C$23*1+C$24*0.5)/SUM(C$23:C$25),0)) -> 0 | D4: =_xlfn.IFS(OR(D$16="",SUM($C$23:$C$26)<$C22,SUM(D$23:D$26)<$C23),"",AND(SUM($C$23:$C$25)=0,$C$26>0),"0",SUM(D$23:D$25)=0,0,SUM(D$23:D$25)<>0,(D$23*1+D$24*0.5)/SUM($C$23:$C$25)) -> 0 | E4: =_xlfn.IFS(OR(E$16="",SUM($C$23:$C$26)<$C22,SUM(E$23:E$26)<$C23),"",AND(SUM($C$23:$C$25)=0,$C$26>0),"n/a",SUM(E$23:E$25)=0,0,SUM(E$23:E$25)<>0,(E$23*1+E$24*0.5)/SUM($C$23:$C$25)) | F4: =_xlfn.IFS(OR(F$16="",SUM($C$23:$C$26)<$C22,SUM(F$23:F$26)<$C23),"",AND(SUM($C$23:$C$25)=0,$C$26>0),"n/a",SUM(F$23:F$25)=0,0,SUM(F$23:F$25)<>0,(F$23*1+F$24*0.5)/SUM($C$23:$C$25)) | G4: =_xlfn.IFS(OR(G$16="",SUM($C$23:$C$26)<$C22,SUM(G$23:G$26)<$C23),"",AND(SUM($C$23:$C$25)=0,$C$26>0),"n/a",SUM(G$23:G$25)=0,0,SUM(G$23:G$25)<>0,(G$23*1+G$24*0.5)/SUM($C$23:$C$25)) | H4: =_xlfn.IFS(OR(H$16="",SUM($C$23:$C$26)<$C22,SUM(H$23:H$26)<$C23),"",AND(SUM($C$23:$C$25)=0,$C$26>0),"n/a",SUM(H$23:H$25)=0,0,SUM(H$23:H$25)<>0,(H$23*1+H$24*0.5)/SUM($C$23:$C$25)) | I4: =_xlfn.IFS(OR(I$16="",SUM($C$23:$C$26)<$C22,SUM(I$23:I$26)<$C23),"",AND(SUM($C$23:$C$25)=0,$C$26>0),"n/a",SUM(I$23:I$25)=0,0,SUM(I$23:I$25)<>0,(I$23*1+I$24*0.5)/SUM($C$23:$C$25)) | J4: =_xlfn.IFS(OR(J$16="",SUM($C$23:$C$26)<$C22,SUM(J$23:J$26)<$C23),"",AND(SUM($C$23:$C$25)=0,$C$26>0),"n/a",SUM(J$23:J$25)=0,0,SUM(J$23:J$25)<>0,(J$23*1+J$24*0.5)/SUM($C$23:$C$25)) | K4: =_xlfn.IFS(OR(K$16="",SUM($C$23:$C$26)<$C22,SUM(K$23:K$26)<$C23),"",AND(SUM($C$23:$C$25)=0,$C$26>0),"n/a",SUM(K$23:K$25)=0,0,SUM(K$23:K$25)<>0,(K$23*1+K$24*0.5)/SUM($C$23:$C$25)) | L4: =_xlfn.IFS(OR(L$16="",SUM($C$23:$C$26)<$C22,SUM(L$23:L$26)<$C23),"",AND(SUM($C$23:$C$25)=0,$C$26>0),"n/a",SUM(L$23:L$25)=0,0,SUM(L$23:L$25)<>0,(L$23*1+L$24*0.5)/SUM($C$23:$C$25)) | ... CY4: =_xlfn.IFS(OR(CY$16="",SUM($C$23:$C$26)<$C22,SUM(CY$23:CY$26)<$C23),"",AND(SUM($C$23:$C$25)=0,$C$26>0),"n/a",SUM(CY$23:CY$25)=0,0,SUM(CY$23:CY$25)<>0,(CY$23*1+CY$24*0.5)/SUM($C$23:$C$25))
A5: Shoring | C5: =IF(OR($C$16="",SUM(C28:C31)<$C27),"",IF(SUM(C$28:C$30)<>0,(C$28*1+C$29*0.5)/SUM(C$28:C$30),0)) -> 0 | D5: =_xlfn.IFS(OR(D$16="",SUM($C$28:$C$31)<$C27,SUM(D$28:D$31)<$C28),"",AND(SUM($C$28:$C$30)=0,$C$31>0),"0",SUM(D$28:D$30)=0,0,SUM(D$28:D$30)<>0,(D$28*1+D$29*0.5)/SUM($C$28:$C$30)) -> 0 | E5: =_xlfn.IFS(OR(E$16="",SUM($C$28:$C$31)<$C27,SUM(E$28:E$31)<$C28),"",AND(SUM($C$28:$C$30)=0,$C$31>0),"n/a",SUM(E$28:E$30)=0,0,SUM(E$28:E$30)<>0,(E$28*1+E$29*0.5)/SUM($C$28:$C$30)) | F5: =_xlfn.IFS(OR(F$16="",SUM($C$28:$C$31)<$C27,SUM(F$28:F$31)<$C28),"",AND(SUM($C$28:$C$30)=0,$C$31>0),"n/a",SUM(F$28:F$30)=0,0,SUM(F$28:F$30)<>0,(F$28*1+F$29*0.5)/SUM($C$28:$C$30)) | G5: =_xlfn.IFS(OR(G$16="",SUM($C$28:$C$31)<$C27,SUM(G$28:G$31)<$C28),"",AND(SUM($C$28:$C$30)=0,$C$31>0),"n/a",SUM(G$28:G$30)=0,0,SUM(G$28:G$30)<>0,(G$28*1+G$29*0.5)/SUM($C$28:$C$30)) | H5: =_xlfn.IFS(OR(H$16="",SUM($C$28:$C$31)<$C27,SUM(H$28:H$31)<$C28),"",AND(SUM($C$28:$C$30)=0,$C$31>0),"n/a",SUM(H$28:H$30)=0,0,SUM(H$28:H$30)<>0,(H$28*1+H$29*0.5)/SUM($C$28:$C$30)) | I5: =_xlfn.IFS(OR(I$16="",SUM($C$28:$C$31)<$C27,SUM(I$28:I$31)<$C28),"",AND(SUM($C$28:$C$30)=0,$C$31>0),"n/a",SUM(I$28:I$30)=0,0,SUM(I$28:I$30)<>0,(I$28*1+I$29*0.5)/SUM($C$28:$C$30)) | J5: =_xlfn.IFS(OR(J$16="",SUM($C$28:$C$31)<$C27,SUM(J$28:J$31)<$C28),"",AND(SUM($C$28:$C$30)=0,$C$31>0),"n/a",SUM(J$28:J$30)=0,0,SUM(J$28:J$30)<>0,(J$28*1+J$29*0.5)/SUM($C$28:$C$30)) | K5: =_xlfn.IFS(OR(K$16="",SUM($C$28:$C$31)<$C27,SUM(K$28:K$31)<$C28),"",AND(SUM($C$28:$C$30)=0,$C$31>0),"n/a",SUM(K$28:K$30)=0,0,SUM(K$28:K$30)<>0,(K$28*1+K$29*0.5)/SUM($C$28:$C$30)) | L5: =_xlfn.IFS(OR(L$16="",SUM($C$28:$C$31)<$C27,SUM(L$28:L$31)<$C28),"",AND(SUM($C$28:$C$30)=0,$C$31>0),"n/a",SUM(L$28:L$30)=0,0,SUM(L$28:L$30)<>0,(L$28*1+L$29*0.5)/SUM($C$28:$C$30)) | ... CY5: =_xlfn.IFS(OR(CY$16="",SUM($C$28:$C$31)<$C27,SUM(CY$28:CY$31)<$C28),"",AND(SUM($C$28:$C$30)=0,$C$31>0),"n/a",SUM(CY$28:CY$30)=0,0,SUM(CY$28:CY$30)<>0,(CY$28*1+CY$29*0.5)/SUM($C$28:$C$30))
A6: DevOps | C6: 0.8
A7: KI | C7: =IF(OR($C$16="",SUM(C33:C36)<32),"",IF(SUM(C$33:C$35)<>0,(C$33*1+C$34*0.5)/SUM(C$33:C$35),0)) -> 0 | D7: =_xlfn.IFS(OR(D$16="",SUM($C$33:$C$36)<$C32,SUM(D$33:D$36)<$C33),"",AND(SUM($C$33:$C$35)=0,$C$36>0),"0",SUM(D$33:D$35)=0,0,SUM(D$33:D$35)<>0,(D$33*1+D$34*0.5)/SUM($C$33:$C$35)) -> 0
A8: Gesamt | D8: =IFERROR(IF(AVERAGE(D3:D7)=0,"",AVERAGE(D3:D7)),"") | E8: =IFERROR(IF(AVERAGE(E3:E7)=0,"",AVERAGE(E3:E7)),"") | F8: =IFERROR(IF(AVERAGE(F3:F7)=0,"",AVERAGE(F3:F7)),"") | G8: =IFERROR(IF(AVERAGE(G3:G7)=0,"",AVERAGE(G3:G7)),"") | H8: =IFERROR(IF(AVERAGE(H3:H7)=0,"",AVERAGE(H3:H7)),"") | I8: =IFERROR(IF(AVERAGE(I3:I7)=0,"",AVERAGE(I3:I7)),"") | J8: =IFERROR(IF(AVERAGE(J3:J7)=0,"",AVERAGE(J3:J7)),"") | K8: =IFERROR(IF(AVERAGE(K3:K7)=0,"",AVERAGE(K3:K7)),"") | ... CY8: =IFERROR(IF(AVERAGE(CY3:CY7)=0,"",AVERAGE(CY3:CY7)),"")
A10: DevOps Umfrage
A12: Details
A13: ℹ️ zur Anzeige der Details bitte ausklappen …
A15: Anzahl der Stati
A16: Capability | B16: Status | C16: =C2 -> PLAN Stand | D16: =_xlfn.IFS(D$2="","",ISERROR(INDIRECT("'"&D$2&"'!$B$1")),INDIRECT("'"&D$2&"'!$B$1"),D$2<>"",D$2) -> IST Stand <Datum> | E16: =_xlfn.IFS(E$2="","",ISERROR(INDIRECT("'"&E$2&"'!$B$1")),INDIRECT("'"&E$2&"'!$B$1"),E$2<>"",E$2) | F16: =_xlfn.IFS(F$2="","",ISERROR(INDIRECT("'"&F$2&"'!$B$1")),INDIRECT("'"&F$2&"'!$B$1"),F$2<>"",F$2) | G16: =_xlfn.IFS(G$2="","",ISERROR(INDIRECT("'"&G$2&"'!$B$1")),INDIRECT("'"&G$2&"'!$B$1"),G$2<>"",G$2) | H16: =_xlfn.IFS(H$2="","",ISERROR(INDIRECT("'"&H$2&"'!$B$1")),INDIRECT("'"&H$2&"'!$B$1"),H$2<>"",H$2) | I16: =_xlfn.IFS(I$2="","",ISERROR(INDIRECT("'"&I$2&"'!$B$1")),INDIRECT("'"&I$2&"'!$B$1"),I$2<>"",I$2) | J16: =_xlfn.IFS(J$2="","",ISERROR(INDIRECT("'"&J$2&"'!$B$1")),INDIRECT("'"&J$2&"'!$B$1"),J$2<>"",J$2) | K16: =_xlfn.IFS(K$2="","",ISERROR(INDIRECT("'"&K$2&"'!$B$1")),INDIRECT("'"&K$2&"'!$B$1"),K$2<>"",K$2) | ... CY16: =_xlfn.IFS(CY$2="","",ISERROR(INDIRECT("'"&CY$2&"'!$B$1")),INDIRECT("'"&CY$2&"'!$B$1"),CY$2<>"",CY$2)
A17: Architektur | B17: Alle | C17: =COUNTIFS(INDIRECT("'"&C$16&"'!$A$2:$A$1000"),$A17) -> 127 | D17: =IF(D$16<>"",COUNTIFS(INDIRECT("'"&D$16&"'!$A$2:$A$1000"),$A17),"") -> 127 | E17: =IF(E$16<>"",COUNTIFS(INDIRECT("'"&E$16&"'!$A$2:$A$1000"),$A17),"") | F17: =IF(F$16<>"",COUNTIFS(INDIRECT("'"&F$16&"'!$A$2:$A$1000"),$A17),"") | G17: =IF(G$16<>"",COUNTIFS(INDIRECT("'"&G$16&"'!$A$2:$A$1000"),$A17),"") | H17: =IF(H$16<>"",COUNTIFS(INDIRECT("'"&H$16&"'!$A$2:$A$1000"),$A17),"") | I17: =IF(I$16<>"",COUNTIFS(INDIRECT("'"&I$16&"'!$A$2:$A$1000"),$A17),"") | J17: =IF(J$16<>"",COUNTIFS(INDIRECT("'"&J$16&"'!$A$2:$A$1000"),$A17),"") | K17: =IF(K$16<>"",COUNTIFS(INDIRECT("'"&K$16&"'!$A$2:$A$1000"),$A17),"") | ... CY17: =IF(CY$16<>"",COUNTIFS(INDIRECT("'"&CY$16&"'!$A$2:$A$1000"),$A17),"")
A18: Architektur | B18: Erfüllt | C18: =COUNTIFS(INDIRECT("'"&C$16&"'!$A$2:$A$1000"),$A18,INDIRECT("'"&C$16&"'!$D$2:$D$1000"),$B18) -> 0 | D18: =IF(D$16<>"",COUNTIFS(INDIRECT("'"&D$16&"'!$A$2:$A$1000"),$A18,INDIRECT("'"&D$16&"'!$E$2:$E$1000"),$B18),"") -> 0 | E18: =IF(E$16<>"",COUNTIFS(INDIRECT("'"&E$16&"'!$A$2:$A$1000"),$A18,INDIRECT("'"&E$16&"'!$E$2:$E$1000"),$B18),"") | F18: =IF(F$16<>"",COUNTIFS(INDIRECT("'"&F$16&"'!$A$2:$A$1000"),$A18,INDIRECT("'"&F$16&"'!$E$2:$E$1000"),$B18),"") | G18: =IF(G$16<>"",COUNTIFS(INDIRECT("'"&G$16&"'!$A$2:$A$1000"),$A18,INDIRECT("'"&G$16&"'!$E$2:$E$1000"),$B18),"") | H18: =IF(H$16<>"",COUNTIFS(INDIRECT("'"&H$16&"'!$A$2:$A$1000"),$A18,INDIRECT("'"&H$16&"'!$E$2:$E$1000"),$B18),"") | I18: =IF(I$16<>"",COUNTIFS(INDIRECT("'"&I$16&"'!$A$2:$A$1000"),$A18,INDIRECT("'"&I$16&"'!$E$2:$E$1000"),$B18),"") | J18: =IF(J$16<>"",COUNTIFS(INDIRECT("'"&J$16&"'!$A$2:$A$1000"),$A18,INDIRECT("'"&J$16&"'!$E$2:$E$1000"),$B18),"") | K18: =IF(K$16<>"",COUNTIFS(INDIRECT("'"&K$16&"'!$A$2:$A$1000"),$A18,INDIRECT("'"&K$16&"'!$E$2:$E$1000"),$B18),"") | ... CY18: =IF(CY$16<>"",COUNTIFS(INDIRECT("'"&CY$16&"'!$A$2:$A$1000"),$A18,INDIRECT("'"&CY$16&"'!$E$2:$E$1000"),$B18),"")
A19: Architektur | B19: Teilweise | C19: =COUNTIFS(INDIRECT("'"&C$16&"'!$A$2:$A$1000"),$A19,INDIRECT("'"&C$16&"'!$D$2:$D$1000"),$B19) -> 0 | D19: =IF(D$16<>"",COUNTIFS(INDIRECT("'"&D$16&"'!$A$2:$A$1000"),$A19,INDIRECT("'"&D$16&"'!$E$2:$E$1000"),$B19),"") -> 0 | E19: =IF(E$16<>"",COUNTIFS(INDIRECT("'"&E$16&"'!$A$2:$A$1000"),$A19,INDIRECT("'"&E$16&"'!$E$2:$E$1000"),$B19),"") | F19: =IF(F$16<>"",COUNTIFS(INDIRECT("'"&F$16&"'!$A$2:$A$1000"),$A19,INDIRECT("'"&F$16&"'!$E$2:$E$1000"),$B19),"") | G19: =IF(G$16<>"",COUNTIFS(INDIRECT("'"&G$16&"'!$A$2:$A$1000"),$A19,INDIRECT("'"&G$16&"'!$E$2:$E$1000"),$B19),"") | H19: =IF(H$16<>"",COUNTIFS(INDIRECT("'"&H$16&"'!$A$2:$A$1000"),$A19,INDIRECT("'"&H$16&"'!$E$2:$E$1000"),$B19),"") | I19: =IF(I$16<>"",COUNTIFS(INDIRECT("'"&I$16&"'!$A$2:$A$1000"),$A19,INDIRECT("'"&I$16&"'!$E$2:$E$1000"),$B19),"") | J19: =IF(J$16<>"",COUNTIFS(INDIRECT("'"&J$16&"'!$A$2:$A$1000"),$A19,INDIRECT("'"&J$16&"'!$E$2:$E$1000"),$B19),"") | K19: =IF(K$16<>"",COUNTIFS(INDIRECT("'"&K$16&"'!$A$2:$A$1000"),$A19,INDIRECT("'"&K$16&"'!$E$2:$E$1000"),$B19),"") | ... CY19: =IF(CY$16<>"",COUNTIFS(INDIRECT("'"&CY$16&"'!$A$2:$A$1000"),$A19,INDIRECT("'"&CY$16&"'!$E$2:$E$1000"),$B19),"")
A20: Architektur | B20: Nicht erfüllt | C20: =COUNTIFS(INDIRECT("'"&C$16&"'!$A$2:$A$1000"),$A20,INDIRECT("'"&C$16&"'!$D$2:$D$1000"),$B20) +COUNTIFS(INDIRECT("'"&C$16&"'!$A$2:$A$1000"),$A20,INDIRECT("'"&C$16&"'!$D$2:$D$1000"),"") -> 127 | D20: =IF(D$16<>"",COUNTIFS(INDIRECT("'"&D$16&"'!$A$2:$A$1000"),$A20,INDIRECT("'"&D$16&"'!$E$2:$E$1000"),$B20),"") -> 0 | E20: =IF(E$16<>"",COUNTIFS(INDIRECT("'"&E$16&"'!$A$2:$A$1000"),$A20,INDIRECT("'"&E$16&"'!$E$2:$E$1000"),$B20),"") | F20: =IF(F$16<>"",COUNTIFS(INDIRECT("'"&F$16&"'!$A$2:$A$1000"),$A20,INDIRECT("'"&F$16&"'!$E$2:$E$1000"),$B20),"") | G20: =IF(G$16<>"",COUNTIFS(INDIRECT("'"&G$16&"'!$A$2:$A$1000"),$A20,INDIRECT("'"&G$16&"'!$E$2:$E$1000"),$B20),"") | H20: =IF(H$16<>"",COUNTIFS(INDIRECT("'"&H$16&"'!$A$2:$A$1000"),$A20,INDIRECT("'"&H$16&"'!$E$2:$E$1000"),$B20),"") | I20: =IF(I$16<>"",COUNTIFS(INDIRECT("'"&I$16&"'!$A$2:$A$1000"),$A20,INDIRECT("'"&I$16&"'!$E$2:$E$1000"),$B20),"") | J20: =IF(J$16<>"",COUNTIFS(INDIRECT("'"&J$16&"'!$A$2:$A$1000"),$A20,INDIRECT("'"&J$16&"'!$E$2:$E$1000"),$B20),"") | K20: =IF(K$16<>"",COUNTIFS(INDIRECT("'"&K$16&"'!$A$2:$A$1000"),$A20,INDIRECT("'"&K$16&"'!$E$2:$E$1000"),$B20),"") | ... CY20: =IF(CY$16<>"",COUNTIFS(INDIRECT("'"&CY$16&"'!$A$2:$A$1000"),$A20,INDIRECT("'"&CY$16&"'!$E$2:$E$1000"),$B20),"")
A21: Architektur | B21: Out of Scope | C21: =COUNTIFS(INDIRECT("'"&C$16&"'!$A$2:$A$1000"),$A21,INDIRECT("'"&C$16&"'!$D$2:$D$1000"),$B21) -> 0 | D21: =IF(D$16<>"",COUNTIFS(INDIRECT("'"&D$16&"'!$A$2:$A$1000"),$A21,INDIRECT("'"&D$16&"'!$E$2:$E$1000"),$B21),"") -> 0 | E21: =IF(E$16<>"",COUNTIFS(INDIRECT("'"&E$16&"'!$A$2:$A$1000"),$A21,INDIRECT("'"&E$16&"'!$E$2:$E$1000"),$B21),"") | F21: =IF(F$16<>"",COUNTIFS(INDIRECT("'"&F$16&"'!$A$2:$A$1000"),$A21,INDIRECT("'"&F$16&"'!$E$2:$E$1000"),$B21),"") | G21: =IF(G$16<>"",COUNTIFS(INDIRECT("'"&G$16&"'!$A$2:$A$1000"),$A21,INDIRECT("'"&G$16&"'!$E$2:$E$1000"),$B21),"") | H21: =IF(H$16<>"",COUNTIFS(INDIRECT("'"&H$16&"'!$A$2:$A$1000"),$A21,INDIRECT("'"&H$16&"'!$E$2:$E$1000"),$B21),"") | I21: =IF(I$16<>"",COUNTIFS(INDIRECT("'"&I$16&"'!$A$2:$A$1000"),$A21,INDIRECT("'"&I$16&"'!$E$2:$E$1000"),$B21),"") | J21: =IF(J$16<>"",COUNTIFS(INDIRECT("'"&J$16&"'!$A$2:$A$1000"),$A21,INDIRECT("'"&J$16&"'!$E$2:$E$1000"),$B21),"") | K21: =IF(K$16<>"",COUNTIFS(INDIRECT("'"&K$16&"'!$A$2:$A$1000"),$A21,INDIRECT("'"&K$16&"'!$E$2:$E$1000"),$B21),"") | ... CY21: =IF(CY$16<>"",COUNTIFS(INDIRECT("'"&CY$16&"'!$A$2:$A$1000"),$A21,INDIRECT("'"&CY$16&"'!$E$2:$E$1000"),$B21),"")
A22: Projektmanagement | B22: Alle | C22: =COUNTIFS(INDIRECT("'"&C$16&"'!$A$2:$A$1000"),$A22) -> 98 | D22: =IF(D$16<>"",COUNTIFS(INDIRECT("'"&D$16&"'!$A$2:$A$1000"),$A22),"") -> 98 | E22: =IF(E$16<>"",COUNTIFS(INDIRECT("'"&E$16&"'!$A$2:$A$1000"),$A22),"") | F22: =IF(F$16<>"",COUNTIFS(INDIRECT("'"&F$16&"'!$A$2:$A$1000"),$A22),"") | G22: =IF(G$16<>"",COUNTIFS(INDIRECT("'"&G$16&"'!$A$2:$A$1000"),$A22),"") | H22: =IF(H$16<>"",COUNTIFS(INDIRECT("'"&H$16&"'!$A$2:$A$1000"),$A22),"") | I22: =IF(I$16<>"",COUNTIFS(INDIRECT("'"&I$16&"'!$A$2:$A$1000"),$A22),"") | J22: =IF(J$16<>"",COUNTIFS(INDIRECT("'"&J$16&"'!$A$2:$A$1000"),$A22),"") | K22: =IF(K$16<>"",COUNTIFS(INDIRECT("'"&K$16&"'!$A$2:$A$1000"),$A22),"") | ... CY22: =IF(CY$16<>"",COUNTIFS(INDIRECT("'"&CY$16&"'!$A$2:$A$1000"),$A22),"")
A23: Projektmanagement | B23: Erfüllt | C23: =COUNTIFS(INDIRECT("'"&C$16&"'!$A$2:$A$1000"),$A23,INDIRECT("'"&C$16&"'!$D$2:$D$1000"),$B23) -> 0 | D23: =IF(D$16<>"",COUNTIFS(INDIRECT("'"&D$16&"'!$A$2:$A$1000"),$A23,INDIRECT("'"&D$16&"'!$E$2:$E$1000"),$B23),"") -> 0 | E23: =IF(E$16<>"",COUNTIFS(INDIRECT("'"&E$16&"'!$A$2:$A$1000"),$A23,INDIRECT("'"&E$16&"'!$E$2:$E$1000"),$B23),"") | F23: =IF(F$16<>"",COUNTIFS(INDIRECT("'"&F$16&"'!$A$2:$A$1000"),$A23,INDIRECT("'"&F$16&"'!$E$2:$E$1000"),$B23),"") | G23: =IF(G$16<>"",COUNTIFS(INDIRECT("'"&G$16&"'!$A$2:$A$1000"),$A23,INDIRECT("'"&G$16&"'!$E$2:$E$1000"),$B23),"") | H23: =IF(H$16<>"",COUNTIFS(INDIRECT("'"&H$16&"'!$A$2:$A$1000"),$A23,INDIRECT("'"&H$16&"'!$E$2:$E$1000"),$B23),"") | I23: =IF(I$16<>"",COUNTIFS(INDIRECT("'"&I$16&"'!$A$2:$A$1000"),$A23,INDIRECT("'"&I$16&"'!$E$2:$E$1000"),$B23),"") | J23: =IF(J$16<>"",COUNTIFS(INDIRECT("'"&J$16&"'!$A$2:$A$1000"),$A23,INDIRECT("'"&J$16&"'!$E$2:$E$1000"),$B23),"") | K23: =IF(K$16<>"",COUNTIFS(INDIRECT("'"&K$16&"'!$A$2:$A$1000"),$A23,INDIRECT("'"&K$16&"'!$E$2:$E$1000"),$B23),"") | ... CY23: =IF(CY$16<>"",COUNTIFS(INDIRECT("'"&CY$16&"'!$A$2:$A$1000"),$A23,INDIRECT("'"&CY$16&"'!$E$2:$E$1000"),$B23),"")
A24: Projektmanagement | B24: Teilweise | C24: =COUNTIFS(INDIRECT("'"&C$16&"'!$A$2:$A$1000"),$A24,INDIRECT("'"&C$16&"'!$D$2:$D$1000"),$B24) -> 0 | D24: =IF(D$16<>"",COUNTIFS(INDIRECT("'"&D$16&"'!$A$2:$A$1000"),$A24,INDIRECT("'"&D$16&"'!$E$2:$E$1000"),$B24),"") -> 0 | E24: =IF(E$16<>"",COUNTIFS(INDIRECT("'"&E$16&"'!$A$2:$A$1000"),$A24,INDIRECT("'"&E$16&"'!$E$2:$E$1000"),$B24),"") | F24: =IF(F$16<>"",COUNTIFS(INDIRECT("'"&F$16&"'!$A$2:$A$1000"),$A24,INDIRECT("'"&F$16&"'!$E$2:$E$1000"),$B24),"") | G24: =IF(G$16<>"",COUNTIFS(INDIRECT("'"&G$16&"'!$A$2:$A$1000"),$A24,INDIRECT("'"&G$16&"'!$E$2:$E$1000"),$B24),"") | H24: =IF(H$16<>"",COUNTIFS(INDIRECT("'"&H$16&"'!$A$2:$A$1000"),$A24,INDIRECT("'"&H$16&"'!$E$2:$E$1000"),$B24),"") | I24: =IF(I$16<>"",COUNTIFS(INDIRECT("'"&I$16&"'!$A$2:$A$1000"),$A24,INDIRECT("'"&I$16&"'!$E$2:$E$1000"),$B24),"") | J24: =IF(J$16<>"",COUNTIFS(INDIRECT("'"&J$16&"'!$A$2:$A$1000"),$A24,INDIRECT("'"&J$16&"'!$E$2:$E$1000"),$B24),"") | K24: =IF(K$16<>"",COUNTIFS(INDIRECT("'"&K$16&"'!$A$2:$A$1000"),$A24,INDIRECT("'"&K$16&"'!$E$2:$E$1000"),$B24),"") | ... CY24: =IF(CY$16<>"",COUNTIFS(INDIRECT("'"&CY$16&"'!$A$2:$A$1000"),$A24,INDIRECT("'"&CY$16&"'!$E$2:$E$1000"),$B24),"")
A25: Projektmanagement | B25: Nicht erfüllt | C25: =COUNTIFS(INDIRECT("'"&C$16&"'!$A$2:$A$1000"),$A25,INDIRECT("'"&C$16&"'!$D$2:$D$1000"),$B25) +COUNTIFS(INDIRECT("'"&C$16&"'!$A$2:$A$1000"),$A25,INDIRECT("'"&C$16&"'!$D$2:$D$1000"),"") -> 98 | D25: =IF(D$16<>"",COUNTIFS(INDIRECT("'"&D$16&"'!$A$2:$A$1000"),$A25,INDIRECT("'"&D$16&"'!$E$2:$E$1000"),$B25),"") -> 0 | E25: =IF(E$16<>"",COUNTIFS(INDIRECT("'"&E$16&"'!$A$2:$A$1000"),$A25,INDIRECT("'"&E$16&"'!$E$2:$E$1000"),$B25),"") | F25: =IF(F$16<>"",COUNTIFS(INDIRECT("'"&F$16&"'!$A$2:$A$1000"),$A25,INDIRECT("'"&F$16&"'!$E$2:$E$1000"),$B25),"") | G25: =IF(G$16<>"",COUNTIFS(INDIRECT("'"&G$16&"'!$A$2:$A$1000"),$A25,INDIRECT("'"&G$16&"'!$E$2:$E$1000"),$B25),"") | H25: =IF(H$16<>"",COUNTIFS(INDIRECT("'"&H$16&"'!$A$2:$A$1000"),$A25,INDIRECT("'"&H$16&"'!$E$2:$E$1000"),$B25),"") | I25: =IF(I$16<>"",COUNTIFS(INDIRECT("'"&I$16&"'!$A$2:$A$1000"),$A25,INDIRECT("'"&I$16&"'!$E$2:$E$1000"),$B25),"") | J25: =IF(J$16<>"",COUNTIFS(INDIRECT("'"&J$16&"'!$A$2:$A$1000"),$A25,INDIRECT("'"&J$16&"'!$E$2:$E$1000"),$B25),"") | K25: =IF(K$16<>"",COUNTIFS(INDIRECT("'"&K$16&"'!$A$2:$A$1000"),$A25,INDIRECT("'"&K$16&"'!$E$2:$E$1000"),$B25),"") | ... CY25: =IF(CY$16<>"",COUNTIFS(INDIRECT("'"&CY$16&"'!$A$2:$A$1000"),$A25,INDIRECT("'"&CY$16&"'!$E$2:$E$1000"),$B25),"")
A26: Projektmanagement | B26: Out of Scope | C26: =COUNTIFS(INDIRECT("'"&C$16&"'!$A$2:$A$1000"),$A26,INDIRECT("'"&C$16&"'!$D$2:$D$1000"),$B26) -> 0 | D26: =IF(D$16<>"",COUNTIFS(INDIRECT("'"&D$16&"'!$A$2:$A$1000"),$A26,INDIRECT("'"&D$16&"'!$E$2:$E$1000"),$B26),"") -> 0 | E26: =IF(E$16<>"",COUNTIFS(INDIRECT("'"&E$16&"'!$A$2:$A$1000"),$A26,INDIRECT("'"&E$16&"'!$E$2:$E$1000"),$B26),"") | F26: =IF(F$16<>"",COUNTIFS(INDIRECT("'"&F$16&"'!$A$2:$A$1000"),$A26,INDIRECT("'"&F$16&"'!$E$2:$E$1000"),$B26),"") | G26: =IF(G$16<>"",COUNTIFS(INDIRECT("'"&G$16&"'!$A$2:$A$1000"),$A26,INDIRECT("'"&G$16&"'!$E$2:$E$1000"),$B26),"") | H26: =IF(H$16<>"",COUNTIFS(INDIRECT("'"&H$16&"'!$A$2:$A$1000"),$A26,INDIRECT("'"&H$16&"'!$E$2:$E$1000"),$B26),"") | I26: =IF(I$16<>"",COUNTIFS(INDIRECT("'"&I$16&"'!$A$2:$A$1000"),$A26,INDIRECT("'"&I$16&"'!$E$2:$E$1000"),$B26),"") | J26: =IF(J$16<>"",COUNTIFS(INDIRECT("'"&J$16&"'!$A$2:$A$1000"),$A26,INDIRECT("'"&J$16&"'!$E$2:$E$1000"),$B26),"") | K26: =IF(K$16<>"",COUNTIFS(INDIRECT("'"&K$16&"'!$A$2:$A$1000"),$A26,INDIRECT("'"&K$16&"'!$E$2:$E$1000"),$B26),"") | ... CY26: =IF(CY$16<>"",COUNTIFS(INDIRECT("'"&CY$16&"'!$A$2:$A$1000"),$A26,INDIRECT("'"&CY$16&"'!$E$2:$E$1000"),$B26),"")
A27: Shoring | B27: Alle | C27: =COUNTIFS(INDIRECT("'"&C$16&"'!$A$2:$A$1000"),$A27) -> 8 | D27: =IF(D$16<>"",COUNTIFS(INDIRECT("'"&D$16&"'!$A$2:$A$1000"),$A27),"") -> 8 | E27: =IF(E$16<>"",COUNTIFS(INDIRECT("'"&E$16&"'!$A$2:$A$1000"),$A27),"") | F27: =IF(F$16<>"",COUNTIFS(INDIRECT("'"&F$16&"'!$A$2:$A$1000"),$A27),"") | G27: =IF(G$16<>"",COUNTIFS(INDIRECT("'"&G$16&"'!$A$2:$A$1000"),$A27),"") | H27: =IF(H$16<>"",COUNTIFS(INDIRECT("'"&H$16&"'!$A$2:$A$1000"),$A27),"") | I27: =IF(I$16<>"",COUNTIFS(INDIRECT("'"&I$16&"'!$A$2:$A$1000"),$A27),"") | J27: =IF(J$16<>"",COUNTIFS(INDIRECT("'"&J$16&"'!$A$2:$A$1000"),$A27),"") | K27: =IF(K$16<>"",COUNTIFS(INDIRECT("'"&K$16&"'!$A$2:$A$1000"),$A27),"") | ... CY27: =IF(CY$16<>"",COUNTIFS(INDIRECT("'"&CY$16&"'!$A$2:$A$1000"),$A27),"")
A28: Shoring | B28: Erfüllt | C28: =COUNTIFS(INDIRECT("'"&C$16&"'!$A$2:$A$1000"),$A28,INDIRECT("'"&C$16&"'!$D$2:$D$1000"),$B28) -> 0 | D28: =IF(D$16<>"",COUNTIFS(INDIRECT("'"&D$16&"'!$A$2:$A$1000"),$A28,INDIRECT("'"&D$16&"'!$E$2:$E$1000"),$B28),"") -> 0 | E28: =IF(E$16<>"",COUNTIFS(INDIRECT("'"&E$16&"'!$A$2:$A$1000"),$A28,INDIRECT("'"&E$16&"'!$E$2:$E$1000"),$B28),"") | F28: =IF(F$16<>"",COUNTIFS(INDIRECT("'"&F$16&"'!$A$2:$A$1000"),$A28,INDIRECT("'"&F$16&"'!$E$2:$E$1000"),$B28),"") | G28: =IF(G$16<>"",COUNTIFS(INDIRECT("'"&G$16&"'!$A$2:$A$1000"),$A28,INDIRECT("'"&G$16&"'!$E$2:$E$1000"),$B28),"") | H28: =IF(H$16<>"",COUNTIFS(INDIRECT("'"&H$16&"'!$A$2:$A$1000"),$A28,INDIRECT("'"&H$16&"'!$E$2:$E$1000"),$B28),"") | I28: =IF(I$16<>"",COUNTIFS(INDIRECT("'"&I$16&"'!$A$2:$A$1000"),$A28,INDIRECT("'"&I$16&"'!$E$2:$E$1000"),$B28),"") | J28: =IF(J$16<>"",COUNTIFS(INDIRECT("'"&J$16&"'!$A$2:$A$1000"),$A28,INDIRECT("'"&J$16&"'!$E$2:$E$1000"),$B28),"") | K28: =IF(K$16<>"",COUNTIFS(INDIRECT("'"&K$16&"'!$A$2:$A$1000"),$A28,INDIRECT("'"&K$16&"'!$E$2:$E$1000"),$B28),"") | ... CY28: =IF(CY$16<>"",COUNTIFS(INDIRECT("'"&CY$16&"'!$A$2:$A$1000"),$A28,INDIRECT("'"&CY$16&"'!$E$2:$E$1000"),$B28),"")
A29: Shoring | B29: Teilweise | C29: =COUNTIFS(INDIRECT("'"&C$16&"'!$A$2:$A$1000"),$A29,INDIRECT("'"&C$16&"'!$D$2:$D$1000"),$B29) -> 0 | D29: =IF(D$16<>"",COUNTIFS(INDIRECT("'"&D$16&"'!$A$2:$A$1000"),$A29,INDIRECT("'"&D$16&"'!$E$2:$E$1000"),$B29),"") -> 0 | E29: =IF(E$16<>"",COUNTIFS(INDIRECT("'"&E$16&"'!$A$2:$A$1000"),$A29,INDIRECT("'"&E$16&"'!$E$2:$E$1000"),$B29),"") | F29: =IF(F$16<>"",COUNTIFS(INDIRECT("'"&F$16&"'!$A$2:$A$1000"),$A29,INDIRECT("'"&F$16&"'!$E$2:$E$1000"),$B29),"") | G29: =IF(G$16<>"",COUNTIFS(INDIRECT("'"&G$16&"'!$A$2:$A$1000"),$A29,INDIRECT("'"&G$16&"'!$E$2:$E$1000"),$B29),"") | H29: =IF(H$16<>"",COUNTIFS(INDIRECT("'"&H$16&"'!$A$2:$A$1000"),$A29,INDIRECT("'"&H$16&"'!$E$2:$E$1000"),$B29),"") | I29: =IF(I$16<>"",COUNTIFS(INDIRECT("'"&I$16&"'!$A$2:$A$1000"),$A29,INDIRECT("'"&I$16&"'!$E$2:$E$1000"),$B29),"") | J29: =IF(J$16<>"",COUNTIFS(INDIRECT("'"&J$16&"'!$A$2:$A$1000"),$A29,INDIRECT("'"&J$16&"'!$E$2:$E$1000"),$B29),"") | K29: =IF(K$16<>"",COUNTIFS(INDIRECT("'"&K$16&"'!$A$2:$A$1000"),$A29,INDIRECT("'"&K$16&"'!$E$2:$E$1000"),$B29),"") | ... CY29: =IF(CY$16<>"",COUNTIFS(INDIRECT("'"&CY$16&"'!$A$2:$A$1000"),$A29,INDIRECT("'"&CY$16&"'!$E$2:$E$1000"),$B29),"")
A30: Shoring | B30: Nicht erfüllt | C30: =COUNTIFS(INDIRECT("'"&C$16&"'!$A$2:$A$1000"),$A30,INDIRECT("'"&C$16&"'!$D$2:$D$1000"),$B30) +COUNTIFS(INDIRECT("'"&C$16&"'!$A$2:$A$1000"),$A30,INDIRECT("'"&C$16&"'!$D$2:$D$1000"),"") -> 8 | D30: =IF(D$16<>"",COUNTIFS(INDIRECT("'"&D$16&"'!$A$2:$A$1000"),$A30,INDIRECT("'"&D$16&"'!$E$2:$E$1000"),$B30),"") -> 0 | E30: =IF(E$16<>"",COUNTIFS(INDIRECT("'"&E$16&"'!$A$2:$A$1000"),$A30,INDIRECT("'"&E$16&"'!$E$2:$E$1000"),$B30),"") | F30: =IF(F$16<>"",COUNTIFS(INDIRECT("'"&F$16&"'!$A$2:$A$1000"),$A30,INDIRECT("'"&F$16&"'!$E$2:$E$1000"),$B30),"") | G30: =IF(G$16<>"",COUNTIFS(INDIRECT("'"&G$16&"'!$A$2:$A$1000"),$A30,INDIRECT("'"&G$16&"'!$E$2:$E$1000"),$B30),"") | H30: =IF(H$16<>"",COUNTIFS(INDIRECT("'"&H$16&"'!$A$2:$A$1000"),$A30,INDIRECT("'"&H$16&"'!$E$2:$E$1000"),$B30),"") | I30: =IF(I$16<>"",COUNTIFS(INDIRECT("'"&I$16&"'!$A$2:$A$1000"),$A30,INDIRECT("'"&I$16&"'!$E$2:$E$1000"),$B30),"") | J30: =IF(J$16<>"",COUNTIFS(INDIRECT("'"&J$16&"'!$A$2:$A$1000"),$A30,INDIRECT("'"&J$16&"'!$E$2:$E$1000"),$B30),"") | K30: =IF(K$16<>"",COUNTIFS(INDIRECT("'"&K$16&"'!$A$2:$A$1000"),$A30,INDIRECT("'"&K$16&"'!$E$2:$E$1000"),$B30),"") | ... CY30: =IF(CY$16<>"",COUNTIFS(INDIRECT("'"&CY$16&"'!$A$2:$A$1000"),$A30,INDIRECT("'"&CY$16&"'!$E$2:$E$1000"),$B30),"")
A31: Shoring | B31: Out of Scope | C31: =COUNTIFS(INDIRECT("'"&C$16&"'!$A$2:$A$1000"),$A31,INDIRECT("'"&C$16&"'!$D$2:$D$1000"),$B31) -> 0 | D31: =IF(D$16<>"",COUNTIFS(INDIRECT("'"&D$16&"'!$A$2:$A$1000"),$A31,INDIRECT("'"&D$16&"'!$E$2:$E$1000"),$B31),"") -> 0 | E31: =IF(E$16<>"",COUNTIFS(INDIRECT("'"&E$16&"'!$A$2:$A$1000"),$A31,INDIRECT("'"&E$16&"'!$E$2:$E$1000"),$B31),"") | F31: =IF(F$16<>"",COUNTIFS(INDIRECT("'"&F$16&"'!$A$2:$A$1000"),$A31,INDIRECT("'"&F$16&"'!$E$2:$E$1000"),$B31),"") | G31: =IF(G$16<>"",COUNTIFS(INDIRECT("'"&G$16&"'!$A$2:$A$1000"),$A31,INDIRECT("'"&G$16&"'!$E$2:$E$1000"),$B31),"") | H31: =IF(H$16<>"",COUNTIFS(INDIRECT("'"&H$16&"'!$A$2:$A$1000"),$A31,INDIRECT("'"&H$16&"'!$E$2:$E$1000"),$B31),"") | I31: =IF(I$16<>"",COUNTIFS(INDIRECT("'"&I$16&"'!$A$2:$A$1000"),$A31,INDIRECT("'"&I$16&"'!$E$2:$E$1000"),$B31),"") | J31: =IF(J$16<>"",COUNTIFS(INDIRECT("'"&J$16&"'!$A$2:$A$1000"),$A31,INDIRECT("'"&J$16&"'!$E$2:$E$1000"),$B31),"") | K31: =IF(K$16<>"",COUNTIFS(INDIRECT("'"&K$16&"'!$A$2:$A$1000"),$A31,INDIRECT("'"&K$16&"'!$E$2:$E$1000"),$B31),"") | ... CY31: =IF(CY$16<>"",COUNTIFS(INDIRECT("'"&CY$16&"'!$A$2:$A$1000"),$A31,INDIRECT("'"&CY$16&"'!$E$2:$E$1000"),$B31),"")
A32: KI | B32: Alle | C32: =COUNTIFS(INDIRECT("'"&C$16&"'!$A$2:$A$1000"),$A32) -> 37 | D32: =IF(D$16<>"",COUNTIFS(INDIRECT("'"&D$16&"'!$A$2:$A$1000"),$A32),"") -> 37
A33: KI | B33: Erfüllt | C33: =COUNTIFS(INDIRECT("'"&C$16&"'!$A$2:$A$1000"),$A33,INDIRECT("'"&C$16&"'!$D$2:$D$1000"),$B33) -> 0 | D33: =IF(D$16<>"",COUNTIFS(INDIRECT("'"&D$16&"'!$A$2:$A$1000"),$A33,INDIRECT("'"&D$16&"'!$E$2:$E$1000"),$B33),"") -> 0
A34: KI | B34: Teilweise | C34: =COUNTIFS(INDIRECT("'"&C$16&"'!$A$2:$A$1000"),$A34,INDIRECT("'"&C$16&"'!$D$2:$D$1000"),$B34) -> 0 | D34: =IF(D$16<>"",COUNTIFS(INDIRECT("'"&D$16&"'!$A$2:$A$1000"),$A34,INDIRECT("'"&D$16&"'!$E$2:$E$1000"),$B34),"") -> 0
A35: KI | B35: Nicht erfüllt | C35: =COUNTIFS(INDIRECT("'"&C$16&"'!$A$2:$A$1000"),$A35,INDIRECT("'"&C$16&"'!$D$2:$D$1000"),$B35) +COUNTIFS(INDIRECT("'"&C$16&"'!$A$2:$A$1000"),$A35,INDIRECT("'"&C$16&"'!$D$2:$D$1000"),"") -> 37 | D35: =IF(D$16<>"",COUNTIFS(INDIRECT("'"&D$16&"'!$A$2:$A$1000"),$A35,INDIRECT("'"&D$16&"'!$E$2:$E$1000"),$B35),"") -> 0
A36: KI | B36: Out of Scope | C36: =COUNTIFS(INDIRECT("'"&C$16&"'!$A$2:$A$1000"),$A36,INDIRECT("'"&C$16&"'!$D$2:$D$1000"),$B36) -> 0 | D36: =IF(D$16<>"",COUNTIFS(INDIRECT("'"&D$16&"'!$A$2:$A$1000"),$A36,INDIRECT("'"&D$16&"'!$E$2:$E$1000"),$B36),"") -> 0
A38: Anzahl Abweichungen zum Plan Stand
A39: Capability | D39: =_xlfn.IFS(D$2="","",ISERROR(INDIRECT("'"&D$2&"'!$B$1")),INDIRECT("'"&D$2&"'!$B$1"),D$2<>"",D$2) -> IST Stand <Datum> | E39: =_xlfn.IFS(E$2="","",ISERROR(INDIRECT("'"&E$2&"'!$B$1")),INDIRECT("'"&E$2&"'!$B$1"),E$2<>"",E$2) | F39: =_xlfn.IFS(F$2="","",ISERROR(INDIRECT("'"&F$2&"'!$B$1")),INDIRECT("'"&F$2&"'!$B$1"),F$2<>"",F$2) | G39: =_xlfn.IFS(G$2="","",ISERROR(INDIRECT("'"&G$2&"'!$B$1")),INDIRECT("'"&G$2&"'!$B$1"),G$2<>"",G$2) | H39: =_xlfn.IFS(H$2="","",ISERROR(INDIRECT("'"&H$2&"'!$B$1")),INDIRECT("'"&H$2&"'!$B$1"),H$2<>"",H$2) | I39: =_xlfn.IFS(I$2="","",ISERROR(INDIRECT("'"&I$2&"'!$B$1")),INDIRECT("'"&I$2&"'!$B$1"),I$2<>"",I$2) | J39: =_xlfn.IFS(J$2="","",ISERROR(INDIRECT("'"&J$2&"'!$B$1")),INDIRECT("'"&J$2&"'!$B$1"),J$2<>"",J$2) | K39: =_xlfn.IFS(K$2="","",ISERROR(INDIRECT("'"&K$2&"'!$B$1")),INDIRECT("'"&K$2&"'!$B$1"),K$2<>"",K$2) | ... CY39: =_xlfn.IFS(CY$2="","",ISERROR(INDIRECT("'"&CY$2&"'!$B$1")),INDIRECT("'"&CY$2&"'!$B$1"),CY$2<>"",CY$2)
A40: Architektur | D40: =IF(D$16<>"",SUMPRODUCT((INDIRECT("'"&D$16&"'!A2:A1000")=$A40)*(INDIRECT("'"&D$16&"'!D2:D1000")<>INDIRECT("'"&D$16&"'!E2:E1000"))),"") -> 0 | E40: =IF(E$16<>"",SUMPRODUCT((INDIRECT("'"&E$16&"'!A2:A1000")=$A40)*(INDIRECT("'"&E$16&"'!D2:D1000")<>INDIRECT("'"&E$16&"'!E2:E1000"))),"") | F40: =IF(F$16<>"",SUMPRODUCT((INDIRECT("'"&F$16&"'!A2:A1000")=$A40)*(INDIRECT("'"&F$16&"'!D2:D1000")<>INDIRECT("'"&F$16&"'!E2:E1000"))),"") | G40: =IF(G$16<>"",SUMPRODUCT((INDIRECT("'"&G$16&"'!A2:A1000")=$A40)*(INDIRECT("'"&G$16&"'!D2:D1000")<>INDIRECT("'"&G$16&"'!E2:E1000"))),"") | H40: =IF(H$16<>"",SUMPRODUCT((INDIRECT("'"&H$16&"'!A2:A1000")=$A40)*(INDIRECT("'"&H$16&"'!D2:D1000")<>INDIRECT("'"&H$16&"'!E2:E1000"))),"") | I40: =IF(I$16<>"",SUMPRODUCT((INDIRECT("'"&I$16&"'!A2:A1000")=$A40)*(INDIRECT("'"&I$16&"'!D2:D1000")<>INDIRECT("'"&I$16&"'!E2:E1000"))),"") | J40: =IF(J$16<>"",SUMPRODUCT((INDIRECT("'"&J$16&"'!A2:A1000")=$A40)*(INDIRECT("'"&J$16&"'!D2:D1000")<>INDIRECT("'"&J$16&"'!E2:E1000"))),"") | K40: =IF(K$16<>"",SUMPRODUCT((INDIRECT("'"&K$16&"'!A2:A1000")=$A40)*(INDIRECT("'"&K$16&"'!D2:D1000")<>INDIRECT("'"&K$16&"'!E2:E1000"))),"") | ... CY40: =IF(CY$16<>"",SUMPRODUCT((INDIRECT("'"&CY$16&"'!A2:A1000")=$A40)*(INDIRECT("'"&CY$16&"'!D2:D1000")<>INDIRECT("'"&CY$16&"'!E2:E1000"))),"")
A41: Projektmanagement | D41: =IF(D$16<>"",SUMPRODUCT((INDIRECT("'"&D$16&"'!A2:A1000")=$A41)*(INDIRECT("'"&D$16&"'!D2:D1000")<>INDIRECT("'"&D$16&"'!E2:E1000"))),"") -> 0 | E41: =IF(E$16<>"",SUMPRODUCT((INDIRECT("'"&E$16&"'!A2:A1000")=$A41)*(INDIRECT("'"&E$16&"'!D2:D1000")<>INDIRECT("'"&E$16&"'!E2:E1000"))),"") | F41: =IF(F$16<>"",SUMPRODUCT((INDIRECT("'"&F$16&"'!A2:A1000")=$A41)*(INDIRECT("'"&F$16&"'!D2:D1000")<>INDIRECT("'"&F$16&"'!E2:E1000"))),"") | G41: =IF(G$16<>"",SUMPRODUCT((INDIRECT("'"&G$16&"'!A2:A1000")=$A41)*(INDIRECT("'"&G$16&"'!D2:D1000")<>INDIRECT("'"&G$16&"'!E2:E1000"))),"") | H41: =IF(H$16<>"",SUMPRODUCT((INDIRECT("'"&H$16&"'!A2:A1000")=$A41)*(INDIRECT("'"&H$16&"'!D2:D1000")<>INDIRECT("'"&H$16&"'!E2:E1000"))),"") | I41: =IF(I$16<>"",SUMPRODUCT((INDIRECT("'"&I$16&"'!A2:A1000")=$A41)*(INDIRECT("'"&I$16&"'!D2:D1000")<>INDIRECT("'"&I$16&"'!E2:E1000"))),"") | J41: =IF(J$16<>"",SUMPRODUCT((INDIRECT("'"&J$16&"'!A2:A1000")=$A41)*(INDIRECT("'"&J$16&"'!D2:D1000")<>INDIRECT("'"&J$16&"'!E2:E1000"))),"") | K41: =IF(K$16<>"",SUMPRODUCT((INDIRECT("'"&K$16&"'!A2:A1000")=$A41)*(INDIRECT("'"&K$16&"'!D2:D1000")<>INDIRECT("'"&K$16&"'!E2:E1000"))),"") | ... CY41: =IF(CY$16<>"",SUMPRODUCT((INDIRECT("'"&CY$16&"'!A2:A1000")=$A41)*(INDIRECT("'"&CY$16&"'!D2:D1000")<>INDIRECT("'"&CY$16&"'!E2:E1000"))),"")
A42: Shoring | D42: =IF(D$16<>"",SUMPRODUCT((INDIRECT("'"&D$16&"'!A2:A1000")=$A42)*(INDIRECT("'"&D$16&"'!D2:D1000")<>INDIRECT("'"&D$16&"'!E2:E1000"))),"") -> 0 | E42: =IF(E$16<>"",SUMPRODUCT((INDIRECT("'"&E$16&"'!A2:A1000")=$A42)*(INDIRECT("'"&E$16&"'!D2:D1000")<>INDIRECT("'"&E$16&"'!E2:E1000"))),"") | F42: =IF(F$16<>"",SUMPRODUCT((INDIRECT("'"&F$16&"'!A2:A1000")=$A42)*(INDIRECT("'"&F$16&"'!D2:D1000")<>INDIRECT("'"&F$16&"'!E2:E1000"))),"") | G42: =IF(G$16<>"",SUMPRODUCT((INDIRECT("'"&G$16&"'!A2:A1000")=$A42)*(INDIRECT("'"&G$16&"'!D2:D1000")<>INDIRECT("'"&G$16&"'!E2:E1000"))),"") | H42: =IF(H$16<>"",SUMPRODUCT((INDIRECT("'"&H$16&"'!A2:A1000")=$A42)*(INDIRECT("'"&H$16&"'!D2:D1000")<>INDIRECT("'"&H$16&"'!E2:E1000"))),"") | I42: =IF(I$16<>"",SUMPRODUCT((INDIRECT("'"&I$16&"'!A2:A1000")=$A42)*(INDIRECT("'"&I$16&"'!D2:D1000")<>INDIRECT("'"&I$16&"'!E2:E1000"))),"") | J42: =IF(J$16<>"",SUMPRODUCT((INDIRECT("'"&J$16&"'!A2:A1000")=$A42)*(INDIRECT("'"&J$16&"'!D2:D1000")<>INDIRECT("'"&J$16&"'!E2:E1000"))),"") | K42: =IF(K$16<>"",SUMPRODUCT((INDIRECT("'"&K$16&"'!A2:A1000")=$A42)*(INDIRECT("'"&K$16&"'!D2:D1000")<>INDIRECT("'"&K$16&"'!E2:E1000"))),"") | ... CY42: =IF(CY$16<>"",SUMPRODUCT((INDIRECT("'"&CY$16&"'!A2:A1000")=$A42)*(INDIRECT("'"&CY$16&"'!D2:D1000")<>INDIRECT("'"&CY$16&"'!E2:E1000"))),"")
A43: KI | D43: =IF(D$16<>"",SUMPRODUCT((INDIRECT("'"&D$16&"'!A2:A1000")=$A43)*(INDIRECT("'"&D$16&"'!D2:D1000")<>INDIRECT("'"&D$16&"'!E2:E1000"))),"") -> 0
A47: STQB-Report | D47: =_xlfn.IFS(D$2="","",ISERROR(INDIRECT("'"&D$2&"'!$B$1")),INDIRECT("'"&D$2&"'!$B$1"),D$2<>"",D$2) -> IST Stand <Datum> | E47: =_xlfn.IFS(E$2="","",ISERROR(INDIRECT("'"&E$2&"'!$B$1")),INDIRECT("'"&E$2&"'!$B$1"),E$2<>"",E$2) | F47: =_xlfn.IFS(F$2="","",ISERROR(INDIRECT("'"&F$2&"'!$B$1")),INDIRECT("'"&F$2&"'!$B$1"),F$2<>"",F$2) | G47: =_xlfn.IFS(G$2="","",ISERROR(INDIRECT("'"&G$2&"'!$B$1")),INDIRECT("'"&G$2&"'!$B$1"),G$2<>"",G$2) | H47: =_xlfn.IFS(H$2="","",ISERROR(INDIRECT("'"&H$2&"'!$B$1")),INDIRECT("'"&H$2&"'!$B$1"),H$2<>"",H$2) | I47: =_xlfn.IFS(I$2="","",ISERROR(INDIRECT("'"&I$2&"'!$B$1")),INDIRECT("'"&I$2&"'!$B$1"),I$2<>"",I$2) | J47: =_xlfn.IFS(J$2="","",ISERROR(INDIRECT("'"&J$2&"'!$B$1")),INDIRECT("'"&J$2&"'!$B$1"),J$2<>"",J$2) | K47: =_xlfn.IFS(K$2="","",ISERROR(INDIRECT("'"&K$2&"'!$B$1")),INDIRECT("'"&K$2&"'!$B$1"),K$2<>"",K$2) | ... CY47: =_xlfn.IFS(CY$2="","",ISERROR(INDIRECT("'"&CY$2&"'!$B$1")),INDIRECT("'"&CY$2&"'!$B$1"),CY$2<>"",CY$2)
...

Sheet PLAN Stand
A1: Capability | B1: Anforderung | C1: Modulname (optional) | D1: Plan-Status | E1: Tailoring-Begründung
A2: Projektmanagement | B2: Projektorganisation (Organigramm) ist dokumentiert und aktuell. | C2: Projektinitialisierung
A3: Projektmanagement | B3: Aufgabenboard (inkl. Kategorie „Offene Punkte") existiert und wird genutzt. | C3: Projektinitialisierung
A4: Projektmanagement | B4: Standardprozesse sind dokumentiert, für Team und Kunde zugänglich und werden gelebt (EPIC-Prozess, Story-Prozess, Defect-Prozess, etc.) | C4: Projektinitialisierung
A5: Projektmanagement | B5: Aktuelle On-/Offboarding-Dokumentation ist vorhanden und um Prozesse, Tools und Admin erweitert. | C5: Projektinitialisierung
A6: Projektmanagement | B6: DoE/DoR/DoD für Epics und Stories sind definiert und im Einsatz. | C6: Projektinitialisierung
A7: Projektmanagement | B7: Entscheidungsdokumentation (Decision Log) wird geführt. | C7: Projektinitialisierung
A8: Projektmanagement | B8: Meeting-Struktur (Dailies, Sprint Planning, Refinement, Review, Retro) ist terminiert und wird durchgeführt. | C8: Projektinitialisierung
A9: Projektmanagement | B9: Administratives Setup (Verbuchung, Heimat-Vorgänge, Stundenerfassung) ist gemäß Standard etabliert. | C9: Projektinitialisierung
A10: Projektmanagement | B10: Rolle Projektleitung und Architekt sind namentlich besetzt; weitere Rollen gemäß Auftrag besetzt. | C10: Projektinitialisierung
A11: Projektmanagement | B11: Kapazitätsplanung wird über Blueprint Capacity-Tool abgebildet. | C11: Capacity Management
A12: Projektmanagement | B12: Basis-Performance-Report (Plan-Ist-Vergleich, Trends, Optimierungsbedarfe) wird regelmäßig erstellt. | C12: Capacity Management
A13: Projektmanagement | B13: Team ist in Heimat allokiert; Rollen und Kapazitäten sind hinterlegt und aktuell (bis 6 Monate in die Zukunft). | C13: Capacity Management
... A276: Projektmanagement | B276: Bei Bedarf existieren separate Testpläne (z. B. Migration, externe Integration, Last-/Performance-, Security-, UAT-, Major-Release-Regression) mit Scope, Entry/Exit-Kriterien, Ressourcen und Stakeholder-Abstimmung. | C276: Test & Quality Management

Sheet IST Stand <Datum>
A1: Capability | B1: Anforderung | C1: Modulname (optional) | D1: Plan-Status | E1: Ist-Status | F1: Begründung der Abweichung | G1: Maßnahmen
A2: Projektmanagement | B2: Projektorganisation (Organigramm) ist dokumentiert und aktuell. | C2: Projektinitialisierung | D2: =IF('PLAN Stand'!D2<>"",'PLAN Stand'!D2,"")
A3: Projektmanagement | B3: Aufgabenboard (inkl. Kategorie „Offene Punkte") existiert und wird genutzt. | C3: Projektinitialisierung | D3: =IF('PLAN Stand'!D3<>"",'PLAN Stand'!D3,"")
A4: Projektmanagement | B4: Standardprozesse sind dokumentiert, für Team und Kunde zugänglich und werden gelebt (EPIC-Prozess, Story-Prozess, Defect-Prozess, etc.) | C4: Projektinitialisierung | D4: =IF('PLAN Stand'!D4<>"",'PLAN Stand'!D4,"")
A5: Projektmanagement | B5: Aktuelle On-/Offboarding-Dokumentation ist vorhanden und um Prozesse, Tools und Admin erweitert. | C5: Projektinitialisierung | D5: =IF('PLAN Stand'!D5<>"",'PLAN Stand'!D5,"")
A6: Projektmanagement | B6: DoE/DoR/DoD für Epics und Stories sind definiert und im Einsatz. | C6: Projektinitialisierung | D6: =IF('PLAN Stand'!D6<>"",'PLAN Stand'!D6,"")
A7: Projektmanagement | B7: Entscheidungsdokumentation (Decision Log) wird geführt. | C7: Projektinitialisierung | D7: =IF('PLAN Stand'!D7<>"",'PLAN Stand'!D7,"")
A8: Projektmanagement | B8: Meeting-Struktur (Dailies, Sprint Planning, Refinement, Review, Retro) ist terminiert und wird durchgeführt. | C8: Projektinitialisierung | D8: =IF('PLAN Stand'!D8<>"",'PLAN Stand'!D8,"")
A9: Projektmanagement | B9: Administratives Setup (Verbuchung, Heimat-Vorgänge, Stundenerfassung) ist gemäß Standard etabliert. | C9: Projektinitialisierung | D9: =IF('PLAN Stand'!D9<>"",'PLAN Stand'!D9,"")
A10: Projektmanagement | B10: Rolle Projektleitung und Architekt sind namentlich besetzt; weitere Rollen gemäß Auftrag besetzt. | C10: Projektinitialisierung | D10: =IF('PLAN Stand'!D10<>"",'PLAN Stand'!D10,"")
A11: Projektmanagement | B11: Kapazitätsplanung wird über Blueprint Capacity-Tool abgebildet. | C11: Capacity Management | D11: =IF('PLAN Stand'!D11<>"",'PLAN Stand'!D11,"")
A12: Projektmanagement | B12: Basis-Performance-Report (Plan-Ist-Vergleich, Trends, Optimierungsbedarfe) wird regelmäßig erstellt. | C12: Capacity Management | D12: =IF('PLAN Stand'!D12<>"",'PLAN Stand'!D12,"")
A13: Projektmanagement | B13: Team ist in Heimat allokiert; Rollen und Kapazitäten sind hinterlegt und aktuell (bis 6 Monate in die Zukunft). | C13: Capacity Management | D13: =IF('PLAN Stand'!D13<>"",'PLAN Stand'!D13,"")
... A95: Projektmanagement | B95: Blueprint Improvement Empfehlungen sind erstellt und an Blueprint-Owner übergeben. | C95: Project Conclusion | D95: =IF('PLAN Stand'!D95<>"",'PLAN Stand'!D95,"")
D96: =IF('PLAN Stand'!D96<>"",'PLAN Stand'!D96,"")
D97: =IF('PLAN Stand'!D97<>"",'PLAN Stand'!D97,"")
D98: =IF('PLAN Stand'!D98<>"",'PLAN Stand'!D98,"")
D99: =IF('PLAN Stand'!D99<>"",'PLAN Stand'!D99,"")
D100: =IF('PLAN Stand'!D100<>"",'PLAN Stand'!D100,"")
A101: Architektur | B101: DoR erfüllt: Produktdokumentation (Zielgruppen, Hauptfunktionen, Rahmen) liegt vor. | C101: Personas | D101: =IF('PLAN Stand'!D101<>"",'PLAN Stand'!D101,"")
A102: Architektur | B102: (Optional) Research-Quellen sind verfügbar bzw. der Zugriff ist geklärt (datenschutzkonform). | C102: Personas | D102: =IF('PLAN Stand'!D102<>"",'PLAN Stand'!D102,"")
A103: Architektur | B103: Kontext- und Accessibility-Kriterien sind definiert (z. B. technische Rahmenbedingungen, Barrieren). | C103: Personas | D103: =IF('PLAN Stand'!D103<>"",'PLAN Stand'!D103,"")
A104: Architektur | B104: Research-Plan bzw. Sampling (bei Primärforschung) ist dokumentiert. | C104: Personas | D104: =IF('PLAN Stand'!D104<>"",'PLAN Stand'!D104,"")
A105: Architektur | B105: Bei Primärforschung: Einwilligungen/Datenschutzfreigaben (z. B. DSGVO/DSB/Legal) sind geklärt und dokumentiert. | C105: Personas | D105: =IF('PLAN Stand'!D105<>"",'PLAN Stand'!D105,"")
A106: Architektur | B106: Persona-Steckbriefe existieren mit Zielen, Needs, Pain Points und Kontext. | C106: Personas | D106: =IF('PLAN Stand'!D106<>"",'PLAN Stand'!D106,"")
A107: Architektur | B107: Personas sind evidenzbasiert (nicht nur Annahmen) und die Herleitung ist nachvollziehbar. | C107: Personas | D107: =IF('PLAN Stand'!D107<>"",'PLAN Stand'!D107,"")
A108: Architektur | B108: Accessibility und Barrieren sind berücksichtigt. | C108: Personas | D108: =IF('PLAN Stand'!D108<>"",'PLAN Stand'!D108,"")
A109: Architektur | B109: Research-Log bzw. Herleitung der Personas ist nachvollziehbar dokumentiert. | C109: Personas | D109: =IF('PLAN Stand'!D109<>"",'PLAN Stand'!D109,"")
A110: Architektur | B110: Traceability ist vorhanden: Personas sind den Hauptfunktionen und (sofern vorhanden) Anwendungsfällen/Use Cases zugeordnet. | C110: Personas | D110: =IF('PLAN Stand'!D110<>"",'PLAN Stand'!D110,"")
A111: Architektur | B111: Review/Abnahme der Personas wurde durchgeführt. | C111: Personas | D111: =IF('PLAN Stand'!D111<>"",'PLAN Stand'!D111,"")
A112: Architektur | B112: DoD des Moduls ist erfüllt. | C112: Personas | D112: =IF('PLAN Stand'!D112<>"",'PLAN Stand'!D112,"")
... A272: KI | B272: Wird im Projekt nachvollzogen, ob eingesetzte Skills tatsächlich helfen (z. B. weniger Aufwand, bessere Qualität, schnellere Bearbeitung oder bessere Wiederholbarkeit)? | C272: n.A. (Bezug auf wiederkehrende Abläufe, Skills & AI Skill DB) | D272: =IF('PLAN Stand'!D272<>"",'PLAN Stand'!D272,"")
A273: Projektmanagement | B273: Projekt-Qualitätsplan ist erstellt, mit Stakeholdern abgestimmt und referenziert das vom Solution Architect gelieferte projektspezifische Testkonzept (Modul Testing Guidelines). | C273: Test & Quality Management
A274: Projektmanagement | B274: Defect-Management-Prozess (Severity/Priority-Matrix, Workflow, SLAs, Eskalationspfade) ist dokumentiert und im Task-Tracking-Tool aktiv. | C274: Test & Quality Management
A275: Projektmanagement | B275: Live Quality Dashboard mit definierten KPIs ist konfiguriert und für alle Stakeholder zugänglich; automatisierte Quality Alerts sind eingerichtet. | C275: Test & Quality Management
A276: Projektmanagement | B276: Bei Bedarf existieren separate Testpläne (z. B. Migration, externe Integration, Last-/Performance-, Security-, UAT-, Major-Release-Regression) mit Scope, Entry/Exit-Kriterien, Ressourcen und Stakeholder-Abstimmung. | C276: Test & Quality Management
